<?xml version="1.0" ?>
<!-- =================================================================================== -->
<!-- |    This document was autogenerated by xacro from urdf/mh12.xacro                | -->
<!-- |    EDITING THIS FILE BY HAND IS NOT RECOMMENDED                                 | -->
<!-- =================================================================================== -->
<robot name="motoman_mh12" xmlns:xacro="http://ros.org/wiki/xacro">
  <!-- Properties -->
  <material name="mh12_deep_blue">
    <color rgba="0.12941 0.14902 0.74902 1"/>
  </material>
  <!-- Links -->
  <link name="base_link">
    <visual>
      <geometry>
        <mesh filename="package://motoman_mh12_support/meshes/visual/base_link.STL"/>
      </geometry>
      <material name="mh12_deep_blue"/>
    </visual>
    <collision>
      <geometry>
        <mesh filename="package://motoman_mh12_support/meshes/collision/base_link.STL"/>
      </geometry>
    </collision>
  </link>
  <link name="link_s">
    <visual>
      <geometry>
        <mesh filename="package://motoman_mh12_support/meshes/visual/link_s.STL"/>
      </geometry>
      <material name="mh12_deep_blue"/>
    </visual>
    <collision>
      <geometry>
        <mesh filename="package://motoman_mh12_support/meshes/collision/link_s.STL"/>
      </geometry>
    </collision>
  </link>
  <link name="link_l">
    <visual>
      <geometry>
        <mesh filename="package://motoman_mh12_support/meshes/visual/link_l.STL"/>
      </geometry>
      <material name="mh12_deep_blue"/>
    </visual>
    <collision>
      <geometry>
        <mesh filename="package://motoman_mh12_support/meshes/collision/link_l.STL"/>
      </geometry>
    </collision>
  </link>
  <link name="link_u">
    <visual>
      <geometry>
        <mesh filename="package://motoman_mh12_support/meshes/visual/link_u.STL"/>
      </geometry>
      <material name="mh12_deep_blue"/>
    </visual>
    <collision>
      <geometry>
        <mesh filename="package://motoman_mh12_support/meshes/collision/link_u.STL"/>
      </geometry>
    </collision>
  </link>
  <link name="link_r">
    <visual>
      <geometry>
        <mesh filename="package://motoman_mh12_support/meshes/visual/link_r.STL"/>
      </geometry>
      <material name="mh12_deep_blue"/>
    </visual>
    <collision>
      <geometry>
        <mesh filename="package://motoman_mh12_support/meshes/collision/link_r.STL"/>
      </geometry>
    </collision>
  </link>
  <link name="link_b">
    <visual>
      <geometry>
        <mesh filename="package://motoman_mh12_support/meshes/visual/link_b.STL"/>
      </geometry>
      <material name="mh12_deep_blue">
      </material>
    </visual>
    <collision>
      <geometry>
        <mesh filename="package://motoman_mh12_support/meshes/collision/link_b.STL"/>
      </geometry>
    </collision>
  </link>
  <link name="link_t">
    <visual>
      <geometry>
        <mesh filename="package://motoman_mh12_support/meshes/visual/link_t.STL"/>
      </geometry>
      <material name="mh12_deep_blue">
      </material>
    </visual>
    <collision>
      <geometry>
        <mesh filename="package://motoman_mh12_support/meshes/collision/link_t.STL"/>
      </geometry>
    </collision>
  </link>
  <link name="tool0"/>
  <!-- JOINTS -->
  <joint name="joint_s" type="revolute">
    <origin xyz="0 0 0.45"/>
    <parent link="base_link"/>
    <child link="link_s"/>
    <axis xyz="0 0 1"/>
    <limit effort="0" lower="-2.9671" upper="2.9671" velocity="3.83972"/>
  </joint>
  <joint name="joint_l" type="revolute">
    <origin xyz="0.155 0 0"/>
    <parent link="link_s"/>
    <child link="link_l"/>
    <axis xyz="0 -1 0"/>
    <limit effort="0" lower="-1.5708" upper="2.7053" velocity="3.49066"/>
  </joint>
  <joint name="joint_u" type="revolute">
    <origin xyz="0 0 0.614"/>
    <parent link="link_l"/>
    <child link="link_u"/>
    <axis xyz="0 -1 0"/>
    <limit effort="0" lower="-3.0543" upper="4.1888" velocity="3.8397"/>
  </joint>
  <joint name="joint_r" type="revolute">
    <origin xyz="0 0 0.2"/>
    <parent link="link_u"/>
    <child link="link_r"/>
    <axis xyz="1 0 0"/>
    <limit effort="22" lower="-3.1416" upper="3.1416" velocity="7.15585"/>
  </joint>
  <joint name="joint_b" type="revolute">
    <origin xyz="0.64 0 0"/>
    <parent link="link_r"/>
    <child link="link_b"/>
    <axis xyz="0 -1 0"/>
    <limit effort="22" lower="-2.3562" upper="2.3562" velocity="7.15585"/>
  </joint>
  <joint name="joint_t" type="revolute">
    <origin xyz="0.1 0 0"/>
    <parent link="link_b"/>
    <child link="link_t"/>
    <axis xyz="1 0 0"/>
    <limit effort="9.8" lower="-6.2832" upper="6.2832" velocity="10.647"/>
  </joint>
  <joint name="link_t-tool0" type="fixed">
    <origin rpy="0 1.5708 0"/>
    <parent link="link_t"/>
    <child link="tool0"/>
  </joint>
  <!-- ref: https://github.com/ros-industrial/abb_experimental/blob/kinetic-devel/abb_irb120_gazebo/urdf/irb120_3_58_macro.xacro -->
  <!-- ref: http://gazebosim.org/tutorials/?tut=ros_control
    hardwareInterface must be included in both actuator and joint tags
    -->
  <!-- transmission list -->
  <transmission name="tran_s">
    <type>transmission_interface/SimpleTransmission</type>
    <joint name="joint_s">
      <hardwareInterface>PositionJointInterface</hardwareInterface>
    </joint>
    <actuator name="motor_s">
      <hardwareInterface>PositionJointInterface</hardwareInterface>
      <mechanicalReduction>1</mechanicalReduction>
    </actuator>
  </transmission>
  <transmission name="tran_l">
    <type>transmission_interface/SimpleTransmission</type>
    <joint name="joint_l">
      <hardwareInterface>PositionJointInterface</hardwareInterface>
    </joint>
    <actuator name="motor_l">
      <hardwareInterface>PositionJointInterface</hardwareInterface>
      <mechanicalReduction>1</mechanicalReduction>
    </actuator>
  </transmission>
  <transmission name="tran_u">
    <type>transmission_interface/SimpleTransmission</type>
    <joint name="joint_u">
      <hardwareInterface>PositionJointInterface</hardwareInterface>
    </joint>
    <actuator name="motor_u">
      <hardwareInterface>PositionJointInterface</hardwareInterface>
      <mechanicalReduction>1</mechanicalReduction>
    </actuator>
  </transmission>
  <transmission name="tran_r">
    <type>transmission_interface/SimpleTransmission</type>
    <joint name="joint_r">
      <hardwareInterface>PositionJointInterface</hardwareInterface>
    </joint>
    <actuator name="motor_r">
      <hardwareInterface>PositionJointInterface</hardwareInterface>
      <mechanicalReduction>1</mechanicalReduction>
    </actuator>
  </transmission>
  <transmission name="tran_b">
    <type>transmission_interface/SimpleTransmission</type>
    <joint name="joint_b">
      <hardwareInterface>PositionJointInterface</hardwareInterface>
    </joint>
    <actuator name="motor_b">
      <hardwareInterface>PositionJointInterface</hardwareInterface>
      <mechanicalReduction>1</mechanicalReduction>
    </actuator>
  </transmission>
  <transmission name="tran_t">
    <type>transmission_interface/SimpleTransmission</type>
    <joint name="joint_t">
      <hardwareInterface>PositionJointInterface</hardwareInterface>
    </joint>
    <actuator name="motor_t">
      <hardwareInterface>PositionJointInterface</hardwareInterface>
      <mechanicalReduction>1</mechanicalReduction>
    </actuator>
  </transmission>
  <!-- gazebo-specific link properties -->
  <gazebo reference="base_link">
    <material>Gazebo/Blue</material>
    <turnGravityOff>false</turnGravityOff>
  </gazebo>
  <gazebo reference="link_s">
    <material>Gazebo/Blue</material>
    <turnGravityOff>false</turnGravityOff>
  </gazebo>
  <gazebo reference="link_l">
    <material>Gazebo/Blue</material>
    <turnGravityOff>false</turnGravityOff>
  </gazebo>
  <gazebo reference="link_u">
    <material>Gazebo/Blue</material>
    <turnGravityOff>false</turnGravityOff>
  </gazebo>
  <gazebo reference="link_b">
    <material>Gazebo/Blue</material>
    <turnGravityOff>false</turnGravityOff>
  </gazebo>
  <gazebo reference="link_r">
    <material>Gazebo/Blue</material>
    <turnGravityOff>false</turnGravityOff>
  </gazebo>
  <gazebo reference="link_t">
    <material>Gazebo/Blue</material>
    <turnGravityOff>false</turnGravityOff>
  </gazebo>
  <gazebo reference="tool0">
    <material>Gazebo/Orange</material>
    <turnGravityOff>true</turnGravityOff>
  </gazebo>
  <!-- ros_control plugin -->
  <gazebo>
    <plugin filename="libgazebo_ros_control.so" name="gazebo_ros_control">
      <robotNamespace>/</robotNamespace>
      <robotSimType>gazebo_ros_control/DefaultRobotHWSim</robotSimType>
    </plugin>
  </gazebo>
  <!-- fix to gazebo world -->
  <link name="world"/>
  <joint name="world-base_link" type="fixed">
    <parent link="world"/>
    <child link="base_link"/>
  </joint>
</robot>

